<mujoco model="robot">
	<compiler angle="radian" autolimits="true" eulerseq="XYZ"/>
	<option integrator="implicitfast"/>
	<asset>
		 
		<mesh file="defeatured_2f-85_pad_open_base.step.stl"/>
		 
		<mesh file="defeatured_2f-85_pad_open_finger1.step.stl"/>
		 
		<mesh file="defeatured_2f-85_pad_open_finger2.step.stl"/>
		 
		<mesh file="defeatured_2f-85_pad_open_finger4.step.stl"/>
		 
		<mesh file="defeatured_2f-85_pad_open_fingertips.step.stl"/>
		 
		<mesh file="defeatured_2f-85_pad_open_finger3.step.stl"/>
		 
		<material name="athens_gray" rgba="0.8980392156862745 0.9176470588235294 0.9294117647058824 1"/>
		 
		<material name="tangerine" rgba="0.9725490196078431 0.5294117647058824 0.00392156862745098 1"/>
		 
		<material name="blizzard_blue" rgba="0.7686274509803922 0.8862745098039215 0.9529411764705882 1"/>
		 
		<material name="lapis_lazuli" rgba="0.23137254901960785 0.3803921568627451 0.7058823529411765 1"/>
		 
		<material name="quick_silver" rgba="0.6470588235294118 0.6470588235294118 0.6470588235294118 1"/>
		 
		<material name="mercury" rgba="0.9176470588235294 0.9176470588235294 0.9176470588235294 1"/>
	</asset>
	<default>
		  
		<joint range="-3.14 3.14" axis="0 0 1"/>
		

		<geom/>
		
  
		<default class="joint_1">
			  
			<joint type="slide"/>
			

		</default>
		<default class="joint_2">
			  
			<joint type="hinge"/>
			

		</default>
	</default>
	<worldbody>
		<body name="base" pos="0 0 0" euler="0 0 0">
			<inertial pos="-0.03052799751152093 0.0049425032238779795 0.08338329699084644" mass="1.773202001091723" fullinertia="0.0013801004091691937 0.001055118006257516 0.0015721753115327532 3.3731884892081616e-09 -6.843047416598052e-08 -8.844783921903561e-07"/>
			<geom type="mesh" pos="-0.030527439877196902 -0.027380400064475154 0.0833605127626829" euler="0.0 -0.0 0.0" mesh="defeatured_2f-85_pad_open_base.step" material="athens_gray"/>
			<body name="defeatured_2f-85_pad_open_finger1.step" pos="-0.06112858430316816 0.027524116205170264 0.08806051276267304" euler="3.1239285222103217e-22 4.1072066650065426e-22 -0.23089479008851274">
				<joint class="joint_2" name="Revolute 21"/>
				<inertial pos="-0.012114025245269625 -0.0008825635070946274 -0.004500000000000002" mass="0.03702478822255647" fullinertia="9.64462394759307e-07 5.946880805810262e-06 6.207094560472298e-06 -4.2245223020935443e-07 -2.3457483389076717e-22 -1.4448875851759613e-22"/>
				<geom type="mesh" pos="0.03060114424019124 -0.054904516296453494 -0.004500000000000032" euler="5.552694887526551e-16 -0.0 3.056718603290575e-17" mesh="defeatured_2f-85_pad_open_finger1.step" material="tangerine"/>
				<body name="defeatured_2f-85_pad_open_finger2.step" pos="-0.03142485315715586 -0.004532229479096506 -0.009000000000000008" euler="-2.86363451347793e-22 -3.7136509070106034e-22 -0.018716797412721885">
					<joint class="joint_2" name="Revolute 11"/>
					<inertial pos="-0.003924470127533157 0.01858080462860411 0.004705531253730937" mass="0.11390989773633624" fullinertia="3.674478049571467e-05 1.4173525219100333e-05 3.163522173561953e-05 6.406730865594384e-06 -2.4726590051380875e-09 1.170705582681303e-08"/>
					<geom type="mesh" pos="0.06202599739734712 -0.050372286817357 0.004700000000009863" euler="-2.880248098420324e-28 -0.0 4.415130620809221e-17" mesh="defeatured_2f-85_pad_open_finger2.step" material="blizzard_blue"/>
					<body name="defeatured_2f-85_pad_open_finger4.step" pos="-0.006783355891963896 0.047033355025695285 0.018299999999999983" euler="2.833850676156566e-22 3.243356716346865e-22 0.2758717619737506">
						<joint class="joint_2" name="Revolute 31"/>
						<inertial pos="0.00943362859374805 0.004700478520750992 -0.013500000049163356" mass="0.056674572788017054" fullinertia="3.3081744012163823e-06 5.0855708135718505e-06 5.137268711528564e-06 -1.209155740828301e-06 8.220839723938627e-15 2.4826359907595606e-14"/>
						<geom type="mesh" pos="0.06880935324840973 -0.09740564186495611 -0.013499999999990117" euler="-7.596118006276859e-17 -0.0 2.069370982433178e-19" mesh="defeatured_2f-85_pad_open_finger4.step" material="lapis_lazuli"/>
						<body name="defeatured_2f-85_pad_open_fingertips.step" pos="0.006101727037762017 0.013015210606457911 -0.013499999999999984" euler="3.141592653589793 -1.1002522143808981e-18 1.6668297362635484e-16">
							<inertial pos="0.01353050151846466 -0.015116764609942268 -2.5057728591004485e-08" mass="0.057454889086897616" fullinertia="9.013175766009459e-06 3.222154754209611e-06 8.253256657590133e-06 1.3960463790975255e-06 -2.423483326977097e-12 1.9393951419518118e-11"/>
							<geom type="mesh" pos="0.06270762621064982 0.11042085247141481 -2.020605904817785e-14" euler="-3.141592653589793 -0.0 -1.4951993258136864e-19" mesh="defeatured_2f-85_pad_open_fingertips.step" material="quick_silver"/>
						</body>
					</body>
				</body>
			</body>
			<body name="defeatured_2f-85_pad_open_finger3.step" pos="-0.043227439877196905 0.03403959993552485 0.09906051276267305" euler="4.928527929664858e-23 4.158027783612048e-22 -0.24497186216435007">
				<joint class="joint_1" name="Cylindrical 21"/>
				<inertial pos="-0.019520660457961275 0.02200036833252042 -0.015300000200522265" mass="0.0793924089105096" fullinertia="2.506772181243261e-05 2.2400230965897807e-05 2.3273447482061028e-05 1.060261429146199e-05 1.3260132184020118e-13 -4.125554879342804e-14"/>
				<geom type="mesh" pos="0.012700000000000003 -0.06142 -0.015299999999990155" euler="-2.953937076191775e-17 -0.0 6.5239977065608e-18" mesh="defeatured_2f-85_pad_open_finger3.step" material="mercury"/>
			</body>
			<body name="defeatured_2f-85_pad_open_finger1.step_2" pos="7.37045486765512e-05 0.027524116205170236 0.08336051276267305" euler="3.141592653589793 -1.6379652789077654e-15 -2.879411418201147">
				<joint class="joint_2" name="Revolute 51"/>
				<inertial pos="-0.012114025245269618 -0.0008825635070946188 -2.4997811173131642e-18" mass="0.03702478822255647" fullinertia="9.64462394759307e-07 5.946880805810264e-06 6.207094560472298e-06 -4.2245223020935453e-07 1.023630221055879e-21 -4.3127223183728355e-23"/>
				<geom type="mesh" pos="0.030601144240191246 -0.054904516296453494 -4.163336342344337e-17" euler="5.553793662240409e-16 2.4000376779406606e-16 -6.700501841877085e-18" mesh="defeatured_2f-85_pad_open_finger1.step" material="tangerine"/>
				<body name="defeatured_2f-85_pad_open_finger2.step_2" pos="-0.03142485315715587 -0.004532229479096487 -0.004500000000000004" euler="-4.474589846259644e-19 2.4000360878088193e-16 -0.002320368938070367">
					<joint class="joint_2" name="Revolute 61"/>
					<inertial pos="-0.003924470127533157 0.018580804628604102 0.004705531253730937" mass="0.11390989773633624" fullinertia="3.674478049571467e-05 1.417352521910033e-05 3.163522173561953e-05 6.406730865594384e-06 -2.472659005138087e-09 1.1707055826813028e-08"/>
					<geom type="mesh" pos="0.06202599739734712 -0.05037228681735699 0.004700000000009863" euler="-2.879231614730963e-28 -8.954236365520967e-32 3.570759635520736e-17" mesh="defeatured_2f-85_pad_open_finger2.step" material="blizzard_blue"/>
					<body name="defeatured_2f-85_pad_open_finger4.step_3" pos="-0.006783355891963896 0.04703335502569529 -0.008900000000000019" euler="-3.141592653589793 -1.7663535488470928e-22 0.26774429673643557">
						<joint class="joint_2" name="Revolute 71"/>
						<inertial pos="0.009433628593748022 -0.004700478520751006 -0.013499999950836622" mass="0.056674572788017054" fullinertia="3.308174401216384e-06 5.085570813571849e-06 5.137268711528564e-06 1.209155740828301e-06 -8.220839997065114e-15 2.4826360088150788e-14"/>
						<geom type="mesh" pos="0.06880935324840971 0.09740564186495608 -0.013500000000009851" euler="3.141592653589793 -1.4932334864727236e-16 3.415672373668205e-19" mesh="defeatured_2f-85_pad_open_finger4.step" material="lapis_lazuli"/>
						<body name="defeatured_2f-85_pad_open_fingertips.step_3" pos="0.006101727037761993 -0.013015210606457897 -0.013499999999999984" euler="-1.1912208418748606e-16 2.017716978438626e-15 3.4156723736646635e-19">
							<inertial pos="0.013530501518464647 -0.01511676460994224 -2.5057728591004485e-08" mass="0.057454889086897616" fullinertia="9.013175766009462e-06 3.22215475420961e-06 8.253256657590133e-06 1.3960463790975255e-06 -2.4234833269770974e-12 1.9393951419518115e-11"/>
							<geom type="mesh" pos="0.06270762621064982 0.11042085247141481 -2.020605904817785e-14" euler="-3.141592653589793 -2.4651903288156613e-32 3.4156723736648016e-19" mesh="defeatured_2f-85_pad_open_fingertips.step" material="quick_silver"/>
						</body>
					</body>
				</body>
			</body>
			<body name="defeatured_2f-85_pad_open_finger3.step_2" pos="-0.017827439877197107 0.03403959993552485 0.09846051276267312" euler="-1.7542426112317116e-15 1.0819382389514748e-15 -1.2006111498958847">
				<joint class="joint_1" name="Cylindrical 11"/>
				<inertial pos="-0.019520660457961282 0.022000368332520392 -0.015300000200522251" mass="0.0793924089105096" fullinertia="2.506772181243261e-05 2.24002309658978e-05 2.3273447482061028e-05 1.0602614291461986e-05 1.3260132184020118e-13 -4.1255548793428037e-14"/>
				<geom type="mesh" pos="0.012700000000000003 -0.061420000000000016 -0.015299999999990141" euler="-2.953937076191795e-17 -0.0 -8.915604857883252e-18" mesh="defeatured_2f-85_pad_open_finger3.step" material="mercury"/>
			</body>
		</body>
	</worldbody>
	<equality>
		<connect anchor="-0.038207917224887415 0.042500324249776594 -0.0017000000000000348" body1="defeatured_2f-85_pad_open_finger3.step" body2="defeatured_2f-85_pad_open_finger4.step"/>
		<connect anchor="-0.03820791722488738 0.04250032424977658 -0.001700000000000021" body1="defeatured_2f-85_pad_open_finger3.step_2" body2="defeatured_2f-85_pad_open_finger4.step_3"/>
	</equality>
</mujoco>
