<mujoco model="robot">
	<compiler angle="radian" autolimits="true" eulerseq="XYZ"/>
	<option integrator="implicitfast"/>
	<asset>
		 
		<mesh file="link.stl"/>
		 
		<material name="cornflower" rgba="0.615686274509804 0.8117647058823529 0.9294117647058824 1"/>
	</asset>
	<default>
		  
		<joint type="hinge" axis="0 0 1"/>
		

		<geom/>
		
  
		<default class="joint_1">
			  
			<joint range="-3.14 3.14"/>
			

		</default>
	</default>
	<worldbody>
		<body name="base" pos="0 0 0" euler="0 0 0">
			<inertial pos="-0.014027284654159314 0.04545103308103392 0.013612788327745002" mass="0.10278949469592548" fullinertia="4.046269979572888e-05 4.071463544027533e-06 3.810439449663344e-05 0.0 0.0 0.0"/>
			<geom type="mesh" pos="-0.019027284654159315 0.020564376492647946 0.013612788327745002" euler="0.0 -0.0 0.0" mesh="link" material="cornflower"/>
			<body name="link" pos="-0.019027284654159315 0.020564376492647942 0.013612788327745" euler="1.5707963267948966 0.9640502007921555 1.5707963267948966">
				<joint name="Revolute 11" range="-6.283185307179586 6.283185307179586"/>
				<inertial pos="-0.02511334341161403 2.4389783105797845e-18 -0.005000000000000001" mass="0.10278949469592548" fullinertia="4.071463544027533e-06 3.810439449663344e-05 4.046269979572888e-05 -4.45644923948132e-21 4.870520322959097e-40 -4.5866496483631585e-40"/>
				<geom type="mesh" pos="-0.05 3.469446951953614e-18 -0.010000000000000002" euler="-1.5707963267948968 -1.5707963267948966 0.0" mesh="link" material="cornflower"/>
				<body name="link_2" pos="-0.05000000000001758 -4.31946145518225e-15 -7.979727989493313e-17" euler="-3.141592653589793 2.3503173767195718e-21 0.9563237873989305">
					<joint class="joint_1" name="Revolute 21"/>
					<inertial pos="-0.025113343411614024 -3.7260404985566607e-19 -0.005000000000000001" mass="0.10278949469592548" fullinertia="4.071463544027533e-06 3.810439449663344e-05 4.046269979572888e-05 -3.531431695704146e-24 4.380435725651371e-40 2.9147475703164608e-40"/>
					<geom type="mesh" pos="-0.049999999999999996 0.0 0.0" euler="1.5707963267948966 1.5707963267948966 0.0" mesh="link" material="cornflower"/>
					<body name="link_3" pos="-0.049999999999999996 0.0 -0.01" euler="-1.102417216658581e-16 1.757585112737597e-16 -2.840739897043759">
						<joint class="joint_1" name="Revolute 31"/>
						<inertial pos="0.024886656588385955 -7.289912220051671e-18 -0.005000000000000003" mass="0.10278949469592548" fullinertia="4.071463544027531e-06 3.810439449663344e-05 4.046269979572888e-05 0.0 -1.0036932552862211e-37 4.3602535617935986e-38"/>
						<geom type="mesh" pos="-1.3877787807814457e-17 -6.938893903907228e-18 -1.734723475976807e-18" euler="1.5707963267948966 1.5707963267948966 0.0" mesh="link" material="cornflower"/>
					</body>
				</body>
			</body>
		</body>
	</worldbody>
	None
</mujoco>
