<mujoco model="robot">
	<compiler angle="radian" autolimits="true" eulerseq="XYZ"/>
	<option integrator="implicitfast"/>
	<asset>
		 
		<mesh file="link.stl"/>
		 
		<material name="cornflower" rgba="0.615686274509804 0.8117647058823529 0.9294117647058824 1"/>
	</asset>
	<default>
		  
		<joint axis="0 0 1" type="hinge"/>
		

		<geom/>
		
  
		<default class="joint_1">
			  
			<joint range="-3.14 3.14"/>
			

		</default>
	</default>
	<worldbody>
		<body name="base" pos="0 0 0" euler="0 0 0">
			<inertial pos="-0.014027284654159314 0.04545103308103392 0.013612788327745002" mass="0.10278949469592548" fullinertia="4.046269979572888e-05 4.071463544027533e-06 3.810439449663344e-05 0.0 0.0 0.0"/>
			<geom type="mesh" pos="-0.019027284654159315 0.020564376492647946 0.013612788327745002" euler="0.0 -0.0 0.0" mesh="link" material="cornflower"/>
			<body name="link" pos="-0.019027284654159315 0.020564376492647963 0.01361278832774504" euler="1.5707963267948966 1.4215831106034549 1.5707963267948966">
				<joint name="Revolute 11" range="-6.283185307179586 6.283185307179586"/>
				<inertial pos="-0.02511334341161403 -4.853152111785978e-18 -0.0049999999999999975" mass="0.10278949469592548" fullinertia="4.071463544027533e-06 3.810439449663345e-05 4.046269979572888e-05 1.0576094027390638e-21 2.214856214304335e-52 1.668613421629983e-51"/>
				<geom type="mesh" pos="-0.05 -5.204170427930421e-18 -0.009999999999999998" euler="-1.5707963267948966 -1.5707963267948966 0.0" mesh="link" material="cornflower"/>
				<body name="link_2" pos="-0.0500000000000002 9.020562075079397e-17 0.0" euler="3.141592653589793 -5.4990036047523246e-27 -1.7200095429863738">
					<joint class="joint_1" name="Revolute 21"/>
					<inertial pos="-0.02511334341161403 1.3526769491670014e-17 -0.005000000000000001" mass="0.10278949469592548" fullinertia="4.071463544027533e-06 3.810439449663344e-05 4.046269979572888e-05 0.0 0.0 1.0548467844780288e-47"/>
					<geom type="mesh" pos="-0.05 1.3877787807814457e-17 0.0" euler="1.5707963267948966 1.5707963267948966 0.0" mesh="link" material="cornflower"/>
					<body name="link_3" pos="-0.04999999999999996 2.7755575615628914e-17 -0.01" euler="4.920734365087288e-27 4.257832819017895e-27 -1.7200095429863782">
						<joint class="joint_1" name="Revolute 31"/>
						<inertial pos="0.024886656588385972 2.0744486385915e-18 -0.005000000000000001" mass="0.10278949469592548" fullinertia="4.071463544027534e-06 3.810439449663345e-05 4.046269979572888e-05 -9.446035884765312e-22 -1.7286910878817924e-51 1.668613421629983e-51"/>
						<geom type="mesh" pos="-6.938893903907228e-18 1.734723475976807e-18 0.0" euler="1.5707963267948966 1.5707963267948966 0.0" mesh="link" material="cornflower"/>
					</body>
				</body>
			</body>
		</body>
	</worldbody>
	<equality>
		<connect anchor="-0.009027284654159315 0.07056437649264814 0.013612788327745054" body1="base" body2="link_3"/>
	</equality>
</mujoco>
