<mujoco model="robot">
	<compiler angle="radian" autolimits="true" eulerseq="XYZ"/>
	<option integrator="implicitfast"/>
	<asset>
		 
		<mesh file="l0.stl"/>
		 
		<mesh file="l1.stl"/>
		 
		<mesh file="l2.stl"/>
		 
		<mesh file="l3.stl"/>
		 
		<mesh file="l4.stl"/>
		 
		<mesh file="l5.stl"/>
		 
		<mesh file="l6.stl"/>
		 
		<mesh file="l7.stl"/>
		 
		<material name="electric_lime" rgba="0.8 1.0 0.2 1"/>
		 
		<material name="quick_silver" rgba="0.6470588235294118 0.6470588235294118 0.6470588235294118 1"/>
		 
		<material name="silver" rgba="0.8 0.8 0.8 1"/>
		 
		<material name="mercury" rgba="0.9176470588235294 0.9176470588235294 0.9176470588235294 1"/>
	</asset>
	<default>
		  
		<joint axis="0 0 1" type="hinge"/>
		

		<geom/>
		
  
		<default class="joint_1">
			  
			<joint range="-2.9670597283903604 2.9670597283903604"/>
			

		</default>
		<default class="joint_2">
			  
			<joint range="-2.0943951023931953 2.0943951023931953"/>
			

		</default>
	</default>
	<worldbody>
		<body name="base" pos="0 0 0" euler="0 0 0">
			<inertial pos="-0.01035107731949609 0.03192923569988471 0.04497926990549461" mass="42.98768750254656" fullinertia="0.1903988096643779 0.24204633327355346 0.2628112127972947 4.845059131105475e-07 0.005311004299230234 -5.6051717850939943e-08"/>
			<geom type="mesh" pos="0.0024707020442987435 0.031929295510053635 -0.026526075098799187" euler="0.0 -0.0 0.0" mesh="l0" material="electric_lime"/>
			<body name="l1" pos="0.0024707020442987504 0.031929295510053635 0.1209739249012008" euler="3.141592653589793 -0.0 -6.043420485784072e-29">
				<joint class="joint_1" name="dof_j11"/>
				<inertial pos="-5.48393368978954e-07 0.03379528857614718 -0.13240387649300087" mass="32.252368538058256" fullinertia="0.258902748850783 0.26120123222902636 0.09676156657994651 3.51731243466588e-07 -9.136048164140038e-07 0.03866152141693182"/>
				<geom type="mesh" pos="0.0 -1.4931491348783655e-31 0.1475" euler="3.141592653589793 -0.0 0.0" mesh="l1" material="electric_lime"/>
				<body name="l2" pos="-5.204170427930421e-18 0.010000000000000002 -0.21250000000000002" euler="-1.5707963267948966 7.888609052210118e-30 -1.1772991650719248e-29">
					<joint class="joint_2" name="dof_j21"/>
					<inertial pos="0.00015560931906714767 0.0588023202941913 -0.05198733353217853" mass="31.019952062412518" fullinertia="0.24016551405095907 0.08647868689608351 0.23878639476140753 0.00025872384255700077 0.00017829567971389603 -0.038360898454444445"/>
					<geom type="mesh" pos="0.00043624370878126394 -0.36 -0.009999999999999877" euler="-1.5707963267948966 -0.0 7.677253948883748e-59" mesh="l2" material="quick_silver"/>
					<body name="l3" pos="-2.5587171270657905e-17 0.1944999999999994 -0.010000000000000182" euler="1.5707963267948963 -1.7536292513590305e-16 -5.204170427931193e-17">
						<joint class="joint_1" name="dof_j31"/>
						<inertial pos="6.336790494515675e-07 -0.029563690547167298 -0.13650514421399274" mass="24.924609587484266" fullinertia="0.19686717680640578 0.186889631475395 0.059720985474427925 4.314951133358754e-07 1.0570799648138968e-06 -0.038258223329299595"/>
						<geom type="mesh" pos="2.168404344971009e-18 4.3018324496289725e-18 0.5545" euler="3.141592653589793 -3.498908159048841e-33 0.0" mesh="l3" material="silver"/>
						<body name="l4" pos="2.168404344971009e-18 -0.010500000000000008 -0.22549999999999903" euler="1.5707963267948966 -8.361759319911739e-32 1.875546704921647e-24">
							<joint class="joint_2" name="dof_j41"/>
							<inertial pos="1.557949561600884e-06 -0.0674206418439649 -0.044765145086959585" mass="21.505090575790533" fullinertia="0.13504568340927875 0.048185429013458916 0.12869367924899325 8.106913392334387e-07 1.8855174843996352e-07 0.02234980562131776"/>
							<geom type="mesh" pos="0.0 0.7800000000000001 -0.010500000000000013" euler="1.5707963267948966 -0.0 -1.1233243501650246e-33" mesh="l4" material="electric_lime"/>
							<body name="l5" pos="-4.336808689942018e-19 -0.17449999999999988 -0.010500000000000016" euler="-1.5707963267948966 2.0362472116017367e-29 1.5765984860918554e-30">
								<joint class="joint_1" name="dof_j51"/>
								<inertial pos="-0.00012006809820828806 0.02138958512371306 -0.08547343539791841" mass="13.294298180252586" fullinertia="0.07911396213211597 0.06830701557184746 0.035077492654825806 -1.2771822057560868e-05 5.82602920038757e-06 0.024257679034287948"/>
								<geom type="mesh" pos="2.168404344971009e-18 -2.637061458344068e-18 0.9545" euler="3.141592653589793 1.1233243501683199e-33 0.0" mesh="l5" material="silver"/>
								<body name="l6" pos="-6.505213034913027e-16 0.07069999999999989 -0.22550000000000314" euler="-1.5707963267948963 -1.807581861967825e-15 1.0378864090540576e-15">
									<joint class="joint_2" name="dof_j61"/>
									<inertial pos="-6.106347671683861e-07 0.0005734026546835302 -0.07103657781028404" mass="14.196752121138323" fullinertia="0.03841788982992332 0.027994846496755495 0.036778587792932915 6.767287473925427e-08 -5.935303711667572e-07 -0.001918455036020094"/>
									<geom type="mesh" pos="0.0 -1.18 -0.0707" euler="-1.5707963267948966 -0.0 -8.728082876802069e-32" mesh="l6" material="silver"/>
									<body name="l7" pos="4.185020385794047e-16 0.07110000000001193 -0.07070000000000101" euler="-1.570796326794896 4.3239879992521566e-15 -3.141592653589793">
										<joint name="dof_j71" range="-3.0543261909900767 3.0543261909900767"/>
										<inertial pos="3.961998951687257e-06 1.9652899206200954e-08 -0.027185443960992872" mass="2.4182903563202385" fullinertia="0.0017223723112730549 0.001695323517714845 0.0026272709862156162 6.152360059049978e-10 2.390517868080172e-07 7.501244200148256e-10"/>
										<geom type="mesh" pos="0.0 1.6218303025255002e-18 1.2511" euler="3.141592653589793 9.686374377277331e-32 0.0" mesh="l7" material="mercury"/>
									</body>
								</body>
							</body>
						</body>
					</body>
				</body>
			</body>
		</body>
	</worldbody>
	None
</mujoco>
