<mujoco model="robot">
	<compiler angle="radian" autolimits="true" eulerseq="XYZ"/>
	<option integrator="implicitfast"/>
	<asset>
		 
		<mesh file="base.stl"/>
		 
		<mesh file="button_mount.stl"/>
		 
		<mesh file="middle_connector.stl"/>
		 
		<mesh file="servo.stl"/>
		 
		<mesh file="box_arm.stl"/>
		 
		<mesh file="box.stl"/>
		 
		<mesh file="u_arm.stl"/>
		 
		<mesh file="ball.stl"/>
		 
		<mesh file="hexapod_(stewart_platform).stl"/>
		 
		<mesh file="top.stl"/>
		 
		<mesh file="screw_rail.stl"/>
		 
		<material name="soap" rgba="0.792156862745098 0.8196078431372549 0.9333333333333333 1"/>
	</asset>
	<default>
		  
		<joint axis="0 0 1"/>
		

		<geom/>
		
  
		<default class="joint_1">
			  
			<joint range="-3.14 3.14"/>
			

		</default>
		<default class="joint_2">
			  
			<joint type="ball"/>
			

		</default>
		<default class="joint_3">
			  
			<joint type="hinge"/>
			

		</default>
		<default class="joint_4">
			  
			<joint type="slide"/>
			

		</default>
		<default class="joint_5">
			  
			<joint range="0 0"/>
			

		</default>
	</default>
	<worldbody>
		<body name="base" pos="0 0 0" euler="0 0 0">
			<inertial pos="0.003117967629805206 0.11894243955612184 0.12339017447084191" mass="1.084002500320617" fullinertia="0.009801282600467443 0.009801282600467443 0.019596061185932958 0.0 0.0 -1.3592985883361564e-18"/>
			<geom type="mesh" pos="0.00311796762980523 0.11894243955612185 0.12039017447084191" euler="1.5707963267948968 -0.0 0.0" mesh="base" material="soap"/>
			<body name="button_mount" pos="-0.103263484107093 0.035828140387154574 0.1263901744708419" euler="-3.141592653589793 2.0057740190981857e-17 -1.3877787807814475e-17">
				<inertial pos="1.0342509904059938e-07 2.790274292868711e-07 -0.0030776805727042097" mass="0.004178185074547277" fullinertia="1.0610446632119487e-07 9.85540779840346e-08 4.16913240202048e-08 -3.6457066800702792e-09 3.0862070260273587e-14 1.3518352218491223e-12"/>
				<geom type="mesh" pos="0.125169820366507 -0.0505718901111524 0.006000000000000005" euler="-1.5707963267948966 1.9018558200823957e-33 0.0" mesh="button_mount" material="soap"/>
				<body name="middle_connector" pos="0.0011238197811400813 0.0027815515659087736 -0.012000000000000038" euler="-1.5707963267948966 0.1668543745305735 -0.38397243543880705">
					<joint class="joint_3" name="Revolute 11"/>
					<inertial pos="1.1102230246251565e-16 1.3659661623548827e-17 -0.0029999999999999433" mass="0.001730290612376196" fullinertia="1.001509274271817e-08 1.0855626506660256e-08 9.929517797780887e-09 2.815167877202859e-10 -3.6487339967776353e-23 4.345654486196076e-23"/>
					<geom type="mesh" pos="0.134999999999993 -0.017999999999999988 -0.0029999999983105104" euler="2.993535260447122e-17 -0.3839724354388087 -7.191500723339768e-18" mesh="middle_connector" material="soap"/>
					<body name="servo" pos="-0.00287031706039996 0.000872513594608243 -0.0029999999999998847" euler="1.5707963267948941 -1.1023594287500056 1.2756938852689352">
						<joint class="joint_3" name="Revolute 21"/>
						<inertial pos="0.025010960800872735 -0.04880528692318122 0.0028802998252503292" mass="0.42666054445271673" fullinertia="0.00020361106021178876 9.684476061580398e-05 0.0002397690426280824 7.419922435731003e-05 1.1445552576495763e-06 -1.7540567805251903e-06"/>
						<geom type="mesh" pos="0.012877003510459492 -0.017888479314477776 0.1373993492856463" euler="-2.4599030941346176 -1.0910323282410475 -3.0066496741783336e-17" mesh="servo" material="soap"/>
						<body name="box_arm" pos="0.03390301453256998 -0.08589060254535605 0.003000000002382" euler="-1.570796326794897 -1.1371444708654197 0.47357040291540237">
							<inertial pos="0.0037816915035426557 0.008166940396641339 -0.1225826243140814" mass="0.21032118837753752" fullinertia="0.0003632192697235533 0.00035960559317072487 2.5750000700225328e-05 -2.130001336181311e-06 4.6369633510927625e-12 1.8721776782147177e-11"/>
							<geom type="mesh" pos="0.12712792114909038 -0.0453100817523563 0.07010745429039472" euler="-1.3157880454001414 0.21209314925985792 1.419588298059437e-17" mesh="box_arm" material="soap"/>
							<body name="box" pos="-5.689893001203927e-16 7.979727989493313e-17 -0.11795639032430691" euler="-3.1415926535897927 2.2299870283681733e-15 -3.5388358909926668e-16">
								<joint class="joint_5" name="Slider 11"/>
								<inertial pos="0.003781686433903253 -0.0081669356224199 -0.014066006578610554" mass="0.1397363514714639" fullinertia="1.8745105677313272e-05 1.9393392171316497e-05 1.9816064282944407e-05 -3.8212030647363365e-07 6.34473643235194e-15 1.84755148985021e-13"/>
								<geom type="mesh" pos="0.12712792114909055 0.04531008175235633 -0.11372066320742899" euler="1.8258046081896517 -0.21209314925985795 -1.419588298059437e-17" mesh="box" material="soap"/>
								<body name="u_arm" pos="-0.004385249213713416 -0.011948622905323697 -0.025200000000000056" euler="5.551115123125789e-17 4.085273785925402e-16 3.6082248300317775e-16">
									<inertial pos="0.008166936060305344 0.0037816868458122573 0.09653292656690432" mass="0.07247635166987312" fullinertia="0.00015358024329046344 0.00015692985039140694 5.57091792444186e-06 -1.974360493859862e-06 -2.547142253348894e-15 -1.501116472654576e-16"/>
									<geom type="mesh" pos="0.13151317036280405 0.05725870465767999 -0.0885206632074289" euler="1.8258046081896517 -0.21209314925985842 7.097941490297184e-18" mesh="u_arm" material="soap"/>
									<body name="ball" pos="0.008166936059518654 0.003781686845805144 0.17520000000000013" euler="-4.0245584642661905e-16 1.9515639104739092e-17 -2.1510571102112423e-16">
										<inertial pos="0.0 -5.551115123125783e-17 5.551115123125783e-17" mass="0.0041102503884466466" fullinertia="4.110250388446647e-08 4.110250388446647e-08 4.1102503884466474e-08 -2.8520591363924755e-25 -2.6738054403679456e-25 0.0"/>
										<geom type="mesh" pos="0.0650287234054862 -0.2882631149999885 0.019881275921146857" euler="0.0 1.474514954580286e-17 0.0" mesh="ball" material="soap"/>
										<body name="hexapod_(stewart_platform)" pos="1.3877787807814457e-17 6.938893903907228e-18 -5.551115123125783e-17" euler="-3.1222722777478604 -0.08532946582185255 -0.07847663327908087">
											<joint class="joint_2" name="Ball 11"/>
											<inertial pos="-4.163336342344337e-17 2.7755575615628914e-17 -0.0019720453168448663" mass="0.0026167634087740145" fullinertia="3.0699318633512794e-08 3.0699318633512794e-08 5.584436817797449e-08 1.7041545193614997e-24 -1.3428374825864035e-24 -4.260386298403748e-25"/>
											<geom type="mesh" pos="0.0650287234054862 0.0198812759211468 0.2912841828118539" euler="-1.5707963267948966 -7.459310946700269e-17 2.7755575615628907e-17" mesh="hexapod_(stewart_platform)" material="soap"/>
											<body name="top" pos="-1.3877787807814457e-17 0.0 -0.000250000000000028" euler="3.141592653589793 5.811323644522305e-17 -8.326672684688675e-17">
												<inertial pos="0.04973205171010513 0.04637588848424498 0.0006847704421956147" mass="0.4547531706772691" fullinertia="0.001087300057051209 0.0010873000570512231 0.002171865342051699 -3.0178638950361887e-20 3.913402831862017e-19 8.05248128559275e-19"/>
												<geom type="mesh" pos="0.0497320517101052 0.04637588848424502 0.2949841828118544" euler="-1.5707963267948974 3.5735303605122226e-16 -2.7755575615628914e-17" mesh="top" material="soap"/>
											</body>
										</body>
									</body>
								</body>
							</body>
							<body name="screw_rail" pos="0.0037816868458051406 0.008166936059518563 -0.1344999999999999" euler="-3.141592653589793 2.923009057020918e-16 -4.1633363423443346e-17">
								<inertial pos="6.785495147709764e-08 4.144883256063103e-09 -0.06995729955840319" mass="0.026593499421766056" fullinertia="4.153689516735656e-05 4.153679708207366e-05 1.0436631487447819e-07 -2.84817322319874e-11 -2.505020006672071e-12 2.814300249830505e-12"/>
								<geom type="mesh" pos="0.1233462343032854 0.05347701781187487 -0.20410745429039467" euler="1.8258046081896517 -0.2120931492598584 0.0" mesh="screw_rail" material="soap"/>
							</body>
						</body>
					</body>
				</body>
			</body>
			<body name="button_mount_2" pos="-0.12205185273670147 0.06837054944496945 0.12639017447084192" euler="-3.141592653589793 4.098284211995214e-17 -2.7755575615628957e-17">
				<inertial pos="1.0342509904059938e-07 2.790274292799322e-07 -0.0030776805727042236" mass="0.004178185074547277" fullinertia="1.0610446632119487e-07 9.85540779840346e-08 4.16913240202048e-08 -3.6457066800702792e-09 3.0862070260273587e-14 1.3518352218491223e-12"/>
				<geom type="mesh" pos="0.125169820366507 -0.05057189011115241 0.0059999999999999915" euler="-1.5707963267948966 -5.440752092893934e-33 0.0" mesh="button_mount" material="soap"/>
				<body name="middle_connector_2" pos="0.0011238197811399286 0.00278155156590881 -0.012000000000000038" euler="-1.5707963267948966 0.153395620630482 -0.38397243543879683">
					<joint class="joint_3" name="Revolute 12"/>
					<inertial pos="1.3877787807814457e-16 1.2350065998742181e-17 -0.002999999999999964" mass="0.001730290612376196" fullinertia="1.0015092742718177e-08 1.0855626506660256e-08 9.929517797780887e-09 2.8151678772028583e-10 -3.48329787426703e-23 4.3430695467818477e-23"/>
					<geom type="mesh" pos="0.13499999999999304 -0.017999999999999988 -0.0029999999983105242" euler="2.2451514453353414e-17 -0.38397243543880866 4.092723988892549e-18" mesh="middle_connector" material="soap"/>
					<body name="servo_2" pos="-0.0028703170603999184 0.0008725135946081597 -0.00299999999999985" euler="1.5707963267948957 -1.1207647173787016 1.275693885268971">
						<joint class="joint_3" name="Revolute 22"/>
						<inertial pos="0.025010960800872752 -0.04880528692318117 0.002880299825250343" mass="0.42666054445271673" fullinertia="0.00020361106021178868 9.684476061580403e-05 0.00023976904262808235 7.419922435731002e-05 1.144555257649555e-06 -1.7540567805252117e-06"/>
						<geom type="mesh" pos="0.012877003510459492 -0.017888479314477734 0.1373993492856463" euler="-2.459903094134618 -1.0910323282410477 -5.261636929812085e-17" mesh="servo" material="soap"/>
						<body name="box_arm_2" pos="0.03390301453257003 -0.08589060254535603 0.003000000002382014" euler="-1.5707963267948972 -1.1371444708654197 0.47357040291540264">
							<inertial pos="0.0037816915035426557 0.008166940396641311 -0.12258262431408146" mass="0.21032118837753752" fullinertia="0.0003632192697235533 0.00035960559317072503 2.575000070022533e-05 -2.130001336181304e-06 4.636963321054667e-12 1.8721776777881277e-11"/>
							<geom type="mesh" pos="0.12712792114909038 -0.045310081752356325 0.0701074542903947" euler="-1.3157880454001414 0.212093149259858 7.097941490297185e-18" mesh="box_arm" material="soap"/>
							<body name="box_2" pos="-2.7755575615628914e-17 -3.122502256758253e-17 -0.11811615339345188" euler="-3.1415926535897927 -8.586881206085157e-17 4.510281037539679e-16">
								<joint class="joint_5" name="Slider 12"/>
								<inertial pos="0.0037816864339032252 -0.0081669356224199 -0.014066006578610561" mass="0.1397363514714639" fullinertia="1.8745105677313282e-05 1.9393392171316494e-05 1.981606428294441e-05 -3.821203064736335e-07 6.344736766477928e-15 1.847551512005177e-13"/>
								<geom type="mesh" pos="0.12712792114909055 0.045310081752356325 -0.11372066320742899" euler="1.8258046081896517 -0.21209314925985795 7.097941490297184e-18" mesh="box" material="soap"/>
								<body name="u_arm_2" pos="-0.0043852492137134436 -0.011948622905323694 -0.02520000000000011" euler="5.898059818321152e-17 3.770855155904603e-16 3.885780586188067e-16">
									<inertial pos="0.008166936060305371 0.0037816868458122647 0.09653292656690435" mass="0.07247635166987312" fullinertia="0.00015358024329046344 0.0001569298503914069 5.5709179244418544e-06 -1.974360493859861e-06 -2.54713491832237e-15 -1.5010653020001615e-16"/>
									<geom type="mesh" pos="0.13151317036280408 0.057258704657679994 -0.08852066320742882" euler="1.8258046081896517 -0.2120931492598584 0.0" mesh="u_arm" material="soap"/>
									<body name="ball_2" pos="0.008166936059518681 0.0037816868458051996 0.17520000000000013" euler="-4.718447854656913e-16 3.534499082302748e-17 -2.4286128663675324e-16">
										<inertial pos="0.0 3.1327334812605436e-19 -5.898059818321144e-17" mass="0.0041102503884466466" fullinertia="4.110250388446647e-08 4.110250388446647e-08 4.1102503884466474e-08 -2.8520591363924755e-25 5.080230336699096e-25 1.4260295681962382e-25"/>
										<geom type="mesh" pos="0.0650287234054862 -0.28826311499998847 0.019881275921146746" euler="-3.469446951953614e-18 -2.970713952610282e-17 -6.938893903907228e-18" mesh="ball" material="soap"/>
										<body name="hexapod_(stewart_platform)_2" pos="5.551115123125783e-17 -3.122502256758253e-17 -4.440892098500626e-16" euler="-3.1317760724900348 -0.10607449607083168 -0.07737548223518871">
											<joint class="joint_2" name="Ball 12"/>
											<inertial pos="-4.163336342344337e-17 2.42861286636753e-17 -0.0019720453168448654" mass="0.0026167634087740145" fullinertia="3.069931863351277e-08 3.069931863351278e-08 5.584436817797449e-08 2.5562317790422486e-24 -1.2386057737032954e-24 -2.515597988428641e-25"/>
											<geom type="mesh" pos="0.06502872340548617 0.019881275921146798 0.2912841828118539" euler="-1.5707963267948966 -6.852157730108389e-17 5.551115123125784e-17" mesh="hexapod_(stewart_platform)" material="soap"/>
										</body>
									</body>
								</body>
							</body>
							<body name="screw_rail_2" pos="0.0037816868458051545 0.008166936059518543 -0.13450000000000012" euler="-3.141592653589793 4.523291463609523e-16 -2.77555756156289e-17">
								<inertial pos="6.785495150485321e-08 4.144883257797827e-09 -0.06995729955840324" mass="0.026593499421766056" fullinertia="4.153689516735653e-05 4.153679708207366e-05 1.0436631487447818e-07 -2.848173223243831e-11 -2.5050200065856313e-12 2.8143002503676297e-12"/>
								<geom type="mesh" pos="0.12334623430328538 0.05347701781187487 -0.20410745429039473" euler="1.8258046081896517 -0.21209314925985845 -1.4195882980594374e-17" mesh="screw_rail" material="soap"/>
							</body>
						</body>
					</body>
				</body>
			</body>
			<body name="button_mount_3" pos="-0.01567040099980281 0.25262862883623394 0.12639017447084192" euler="-3.141592653589793 4.098284211995214e-17 -2.7755575615628957e-17">
				<inertial pos="1.0342509904059938e-07 2.7902742929380997e-07 -0.0030776805727042236" mass="0.004178185074547277" fullinertia="1.0610446632119487e-07 9.85540779840346e-08 4.16913240202048e-08 -3.6457066800702792e-09 3.0862070260273587e-14 1.3518352218491223e-12"/>
				<geom type="mesh" pos="0.125169820366507 -0.050571890111152394 0.0059999999999999915" euler="-1.5707963267948966 -5.440752092893934e-33 0.0" mesh="button_mount" material="soap"/>
				<body name="middle_connector_3" pos="0.0011238197811398922 0.002781551565909015 -0.012000000000000066" euler="-1.5707963267948966 0.38438416815020726 -0.38397243543881426">
					<joint class="joint_3" name="Revolute 13"/>
					<inertial pos="8.326672684688674e-17 3.276212042101122e-17 -0.002999999999999919" mass="0.001730290612376196" fullinertia="1.001509274271817e-08 1.0855626506660253e-08 9.929517797780883e-09 2.815167877202847e-10 -3.530386689138138e-23 4.312305074247743e-23"/>
					<geom type="mesh" pos="0.13499999999999296 -0.017999999999999974 -0.002999999998310479" euler="2.9935352604471227e-17 -0.3839724354388087 -8.512865896896504e-17" mesh="middle_connector" material="soap"/>
					<body name="servo_3" pos="-0.0028703170603996964 0.000872513594608465 -0.0030000000000002525" euler="1.5707963267948952 -1.3432835085036121 1.2756938852688733">
						<joint class="joint_3" name="Revolute 23"/>
						<inertial pos="0.025010960800872763 -0.04880528692318124 0.002880299825250343" mass="0.42666054445271673" fullinertia="0.0002036110602117887 9.684476061580398e-05 0.00023976904262808235 7.419922435731002e-05 1.1445552576495589e-06 -1.754056780525197e-06"/>
						<geom type="mesh" pos="0.01287700351045952 -0.01788847931447779 0.1373993492856463" euler="-2.459903094134618 -1.0910323282410477 5.261636929812085e-17" mesh="servo" material="soap"/>
						<body name="box_arm_3" pos="0.03390301453257002 -0.08589060254535608 0.003000000002382" euler="-1.570796326794897 -1.1371444708654197 0.4735704029154026">
							<inertial pos="0.0037816915035426973 0.008166940396641327 -0.12258262431408143" mass="0.21032118837753752" fullinertia="0.0003632192697235533 0.000359605593170725 2.575000070022534e-05 -2.1300013361813126e-06 4.636963329276816e-12 1.8721776793478446e-11"/>
							<geom type="mesh" pos="0.12712792114909044 -0.04531008175235631 0.07010745429039475" euler="-1.3157880454001414 0.21209314925985803 0.0" mesh="box_arm" material="soap"/>
							<body name="box_3" pos="2.0816681711721685e-17 8.326672684688674e-17 -0.12197504630488348" euler="3.1415926535897922 1.0581813203458467e-16 -3.469446951953596e-17">
								<joint class="joint_5" name="Slider 13"/>
								<inertial pos="0.003781686433903267 -0.0081669356224199 -0.014066006578610585" mass="0.1397363514714639" fullinertia="1.8745105677313276e-05 1.9393392171316497e-05 1.981606428294441e-05 -3.8212030647363344e-07 6.344736508852584e-15 1.847551479421594e-13"/>
								<geom type="mesh" pos="0.12712792114909058 0.04531008175235633 -0.11372066320742902" euler="1.8258046081896517 -0.21209314925985798 0.0" mesh="box" material="soap"/>
								<body name="u_arm_3" pos="-0.004385249213713416 -0.01194862290532371 -0.02520000000000011" euler="-5.551115123125789e-17 3.400058012914559e-16 4.024558464266213e-16">
									<inertial pos="0.008166936060305344 0.003781686845812264 0.0965329265669043" mass="0.07247635166987312" fullinertia="0.0001535802432904633 0.0001569298503914069 5.570917924441856e-06 -1.9743604938598636e-06 -2.5471418444790156e-15 -1.501175241944515e-16"/>
									<geom type="mesh" pos="0.13151317036280402 0.05725870465767999 -0.08852066320742888" euler="1.8258046081896517 -0.21209314925985842 1.4195882980594374e-17" mesh="u_arm" material="soap"/>
									<body name="ball_3" pos="0.00816693605951866 0.0037816868458051822 0.17520000000000008" euler="-2.775557561562889e-17 -5.204170427930428e-18 -2.1510571102112438e-16">
										<inertial pos="0.0 5.518162571645724e-19 -6.938893903907228e-18" mass="0.0041102503884466466" fullinertia="4.110250388446648e-08 4.110250388446647e-08 4.1102503884466474e-08 -2.8520591363924755e-25 7.130147840981191e-26 -2.2816473091139807e-24"/>
										<geom type="mesh" pos="0.06502872340548621 -0.28826311499998847 0.0198812759211468" euler="-2.7755575615628914e-17 -1.7347234759768067e-18 0.0" mesh="ball" material="soap"/>
										<body name="hexapod_(stewart_platform)_3" pos="-1.734723475976807e-17 -1.1102230246251565e-16 -1.1102230246251565e-16" euler="2.8449822319047353 -0.015571854556411342 -0.089956107144227">
											<joint class="joint_2" name="Ball 13"/>
											<inertial pos="-4.163336342344337e-17 2.7755575615628914e-17 -0.00197204531684481" mass="0.0026167634087740145" fullinertia="3.0699318633512794e-08 3.069931863351278e-08 5.584436817797449e-08 1.7041545193614993e-24 -2.071674454759072e-24 -3.8540483922676775e-26"/>
											<geom type="mesh" pos="0.06502872340548618 0.0198812759211468 0.291284182811854" euler="-1.5707963267948966 -6.505213034913025e-17 2.7755575615628907e-17" mesh="hexapod_(stewart_platform)" material="soap"/>
										</body>
									</body>
								</body>
							</body>
							<body name="screw_rail_3" pos="0.0037816868458051996 0.008166936059518598 -0.13449999999999995" euler="-3.141592653589793 2.532696274926138e-16 -2.0816681711721682e-17">
								<inertial pos="6.785495147709764e-08 4.144883223103357e-09 -0.06995729955840316" mass="0.026593499421766056" fullinertia="4.153689516735653e-05 4.153679708207366e-05 1.0436631487447893e-07 -2.8481732233271647e-11 -2.505020005781818e-12 2.8143002509461003e-12"/>
								<geom type="mesh" pos="0.12334623430328537 0.05347701781187483 -0.20410745429039465" euler="1.8258046081896517 -0.21209314925985845 -2.839176596118875e-17" mesh="screw_rail" material="soap"/>
							</body>
						</body>
					</body>
				</body>
			</body>
			<body name="button_mount_4" pos="0.021906336259414183 0.25262862883623394 0.12639017447084192" euler="-3.141592653589793 8.196568423990438e-17 -5.551115123125797e-17">
				<inertial pos="1.0342509904059938e-07 2.790274292313599e-07 -0.0030776805727042375" mass="0.004178185074547277" fullinertia="1.0610446632119487e-07 9.85540779840346e-08 4.16913240202048e-08 -3.6457066800702792e-09 3.0862070260273587e-14 1.3518352218491223e-12"/>
				<geom type="mesh" pos="0.125169820366507 -0.05057189011115246 0.005999999999999978" euler="-1.5707963267948966 -4.814824860968027e-33 6.162975822039155e-33" mesh="button_mount" material="soap"/>
				<body name="middle_connector_4" pos="0.001123819781139613 0.0027815515659088737 -0.011999999999999816" euler="-1.5707963267948966 0.40765516437795585 -0.38397243543881543">
					<joint class="joint_3" name="Revolute 14"/>
					<inertial pos="1.3877787807814457e-16 3.351737954953137e-17 -0.002999999999999926" mass="0.001730290612376196" fullinertia="1.001509274271817e-08 1.0855626506660256e-08 9.929517797780882e-09 2.815167877202858e-10 -3.5714522936309254e-23 4.31754152818851e-23"/>
					<geom type="mesh" pos="0.13499999999999301 -0.017999999999999974 -0.002999999998310493" euler="2.9935352604471227e-17 -0.3839724354388086 -6.17416647467219e-17" mesh="middle_connector" material="soap"/>
					<body name="servo_4" pos="-0.0028703170603998907 0.0008725135946082707 -0.003000000000000054" euler="1.5707963267948972 -1.3456530721804194 1.2756938852689161">
						<joint class="joint_3" name="Revolute 24"/>
						<inertial pos="0.025010960800872735 -0.04880528692318123 0.0028802998252503154" mass="0.42666054445271673" fullinertia="0.0002036110602117887 9.684476061580401e-05 0.00023976904262808235 7.419922435731003e-05 1.1445552576495589e-06 -1.7540567805252136e-06"/>
						<geom type="mesh" pos="0.012877003510459492 -0.01788847931447779 0.13739934928564626" euler="-2.459903094134618 -1.0910323282410477 -5.261636929812085e-17" mesh="servo" material="soap"/>
						<body name="box_arm_4" pos="0.03390301453257 -0.0858906025453561 0.003000000002381993" euler="-1.5707963267948972 -1.1371444708654197 0.47357040291540253">
							<inertial pos="0.0037816915035426557 0.008166940396641367 -0.12258262431408143" mass="0.21032118837753752" fullinertia="0.0003632192697235533 0.00035960559317072487 2.575000070022534e-05 -2.1300013361813046e-06 4.636963341873097e-12 1.872177677435241e-11"/>
							<geom type="mesh" pos="0.12712792114909038 -0.04531008175235627 0.07010745429039475" euler="-1.3157880454001414 0.21209314925985798 2.839176596118874e-17" mesh="box_arm" material="soap"/>
							<body name="box_4" pos="-2.0816681711721685e-17 4.3021142204224816e-16 -0.12212924739576458" euler="-3.141592653589793 1.1917550279960606e-15 7.355227538141627e-16">
								<joint class="joint_5" name="Slider 14"/>
								<inertial pos="0.003781686433903253 -0.008166935622419862 -0.014066006578610471" mass="0.1397363514714639" fullinertia="1.8745105677313282e-05 1.9393392171316494e-05 1.9816064282944413e-05 -3.821203064736341e-07 6.344735586038751e-15 1.8475514983205395e-13"/>
								<geom type="mesh" pos="0.12712792114909058 0.04531008175235636 -0.11372066320742893" euler="1.8258046081896517 -0.2120931492598579 -2.8391765961188735e-17" mesh="box" material="soap"/>
								<body name="u_arm_4" pos="-0.004385249213713431 -0.01194862290532367 -0.025200000000000056" euler="0.0 3.9031278209478347e-16 5.551115123125809e-16">
									<inertial pos="0.008166936060305358 0.0037816868458123076 0.09653292656690435" mass="0.07247635166987312" fullinertia="0.00015358024329046338 0.00015692985039140688 5.570917924441858e-06 -1.974360493859866e-06 -2.54714536209921e-15 -1.5010899660366648e-16"/>
									<geom type="mesh" pos="0.13151317036280405 0.05725870465768003 -0.08852066320742885" euler="1.8258046081896517 -0.21209314925985842 -1.419588298059437e-17" mesh="u_arm" material="soap"/>
									<body name="ball_4" pos="0.008166936059518655 0.0037816868458053488 0.17520000000000024" euler="-4.440892098500624e-16 2.6020852139652143e-17 -2.9143354396410404e-16">
										<inertial pos="1.3877787807814457e-17 1.1036325143291449e-18 -8.673617379884035e-17" mass="0.0041102503884466466" fullinertia="4.110250388446647e-08 4.110250388446648e-08 4.1102503884466474e-08 -3.958027151019333e-42 1.1479437019748901e-41 -6.844941927341942e-24"/>
										<geom type="mesh" pos="0.06502872340548621 -0.2882631149999885 0.019881275921146746" euler="-1.1102230246251565e-16 1.734723475976807e-18 0.0" mesh="ball" material="soap"/>
										<body name="hexapod_(stewart_platform)_4" pos="-2.0816681711721685e-17 -2.498001805406602e-16 1.1102230246251565e-16" euler="2.8315968761106904 0.0027465100563963465 -0.09556564946853972">
											<joint class="joint_2" name="Ball 14"/>
											<inertial pos="-1.3877787807814457e-17 3.469446951953614e-18 -0.001972045316844755" mass="0.0026167634087740145" fullinertia="3.069931863351277e-08 3.069931863351278e-08 5.584436817797448e-08 1.704154519361499e-24 -1.8416628464545305e-24 5.619769769152086e-25"/>
											<geom type="mesh" pos="0.06502872340548618 0.019881275921146777 0.291284182811854" euler="-1.5707963267948966 -6.93889390390723e-17 5.551115123125784e-17" mesh="hexapod_(stewart_platform)" material="soap"/>
										</body>
									</body>
								</body>
							</body>
							<body name="screw_rail_4" pos="0.0037816868458051857 0.008166936059518612 -0.13449999999999995" euler="-3.141592653589793 4.2847669856627135e-16 -1.3183898417423734e-16">
								<inertial pos="6.785495150485321e-08 4.1448832786145084e-09 -0.06995729955840319" mass="0.026593499421766056" fullinertia="4.153689516735656e-05 4.153679708207365e-05 1.0436631487447811e-07 -2.8481732230909183e-11 -2.505020006461752e-12 2.8143002498535373e-12"/>
								<geom type="mesh" pos="0.12334623430328542 0.05347701781187489 -0.20410745429039467" euler="1.8258046081896517 -0.21209314925985845 0.0" mesh="screw_rail" material="soap"/>
							</body>
						</body>
					</body>
				</body>
			</body>
			<body name="button_mount_5" pos="0.12828778799632987 0.06837054944497942 0.12639017447084192" euler="-3.141592653589793 8.196568423990438e-17 -5.551115123125797e-17">
				<inertial pos="1.034250990128438e-07 2.790274292660544e-07 -0.0030776805727042097" mass="0.004178185074547277" fullinertia="1.0610446632119487e-07 9.85540779840346e-08 4.16913240202048e-08 -3.6457066800702792e-09 3.0862070260273587e-14 1.3518352218491223e-12"/>
				<geom type="mesh" pos="0.12516982036650698 -0.05057189011115242 0.006000000000000005" euler="-1.5707963267948966 -4.814824860968027e-33 6.162975822039155e-33" mesh="button_mount" material="soap"/>
				<body name="middle_connector_5" pos="0.001123819781139429 0.002781551565908868 -0.01200000000000015" euler="-1.5707963267948963 0.4853013037943363 -0.3839724354387994">
					<joint class="joint_3" name="Revolute 15"/>
					<inertial pos="1.1102230246251565e-16 -1.0779493811498766e-18 -0.002999999999999974" mass="0.001730290612376196" fullinertia="1.0015092742718173e-08 1.0855626506660256e-08 9.929517797780887e-09 2.8151678772028697e-10 -3.524656904894681e-23 4.371974443649164e-23"/>
					<geom type="mesh" pos="0.13499999999999301 -0.018000000000000002 -0.0029999999983105347" euler="5.987070520894244e-17 -0.3839724354388087 -2.8064393066691767e-18" mesh="middle_connector" material="soap"/>
					<body name="servo_5" pos="-0.002870317060399946 0.0008725135946082707 -0.0030000000000000096" euler="1.5707963267948961 -1.0367197611594228 1.2756938852689217">
						<joint class="joint_3" name="Revolute 25"/>
						<inertial pos="0.02501096080087277 -0.0488052869231812 0.0028802998252503154" mass="0.42666054445271673" fullinertia="0.00020361106021178876 9.684476061580401e-05 0.00023976904262808243 7.419922435731007e-05 1.1445552576495693e-06 -1.7540567805251922e-06"/>
						<geom type="mesh" pos="0.012877003510459534 -0.017888479314477755 0.1373993492856463" euler="-2.4599030941346176 -1.0910323282410475 2.330153497488208e-16" mesh="servo" material="soap"/>
						<body name="box_arm_5" pos="0.033903014532570025 -0.085890602545356 0.003000000002381986" euler="-1.5707963267948968 -1.1371444708654195 0.47357040291540253">
							<inertial pos="0.0037816915035426557 0.008166940396641332 -0.12258262431408146" mass="0.21032118837753752" fullinertia="0.0003632192697235534 0.00035960559317072487 2.575000070022534e-05 -2.1300013361813113e-06 4.636963363048921e-12 1.872177677435241e-11"/>
							<geom type="mesh" pos="0.12712792114909038 -0.045310081752356304 0.07010745429039475" euler="-1.3157880454001416 0.21209314925985792 1.419588298059437e-17" mesh="box_arm" material="soap"/>
							<body name="box_5" pos="-5.551115123125783e-17 -1.214306433183765e-16 -0.11776367988280467" euler="3.141592653589793 1.456625618734265e-15 -6.591949208711821e-16">
								<joint class="joint_5" name="Slider 15"/>
								<inertial pos="0.0037816864339032946 -0.008166935622419894 -0.014066006578610502" mass="0.1397363514714639" fullinertia="1.8745105677313276e-05 1.9393392171316494e-05 1.9816064282944413e-05 -3.821203064736335e-07 6.3447351246318346e-15 1.8475515035348475e-13"/>
								<geom type="mesh" pos="0.1271279211490906 0.04531008175235633 -0.11372066320742896" euler="1.8258046081896517 -0.21209314925985795 0.0" mesh="box" material="soap"/>
								<body name="u_arm_5" pos="-0.0043852492137134436 -0.011948622905323687 -0.0252" euler="2.4286128663675324e-16 2.0914259907245494e-16 4.440892098500651e-16">
									<inertial pos="0.008166936060305344 0.0037816868458122495 0.09653292656690435" mass="0.07247635166987312" fullinertia="0.00015358024329046338 0.00015692985039140688 5.5709179244418595e-06 -1.974360493859861e-06 -2.5471323740930667e-15 -1.5010056114195185e-16"/>
									<geom type="mesh" pos="0.13151317036280402 0.057258704657679974 -0.08852066320742885" euler="1.8258046081896517 -0.2120931492598585 1.419588298059437e-17" mesh="u_arm" material="soap"/>
									<body name="ball_5" pos="0.008166936059518681 0.003781686845805184 0.1752000000000003" euler="-4.1286418728247974e-16 -2.493664996716663e-18 -1.6653345369377368e-16">
										<inertial pos="2.7755575615628914e-17 5.551115123125783e-17 0.0" mass="0.0041102503884466466" fullinertia="4.1102503884466455e-08 4.110250388446647e-08 4.1102503884466474e-08 -2.8520591363924755e-25 4.01070816055192e-25 -7.130147840981189e-26"/>
										<geom type="mesh" pos="0.06502872340548621 -0.2882631149999884 0.0198812759211468" euler="-1.734723475976807e-18 2.059984127722459e-18 0.0" mesh="ball" material="soap"/>
										<body name="hexapod_(stewart_platform)_5" pos="0.0 -1.1622647289044608e-16 -1.1102230246251565e-16" euler="3.0620852083529417 0.2244468917741129 -0.07653879468236917">
											<joint class="joint_2" name="Ball 15"/>
											<inertial pos="-2.7755575615628914e-17 3.122502256758253e-17 -0.0019720453168447553" mass="0.0026167634087740145" fullinertia="3.069931863351277e-08 3.0699318633512794e-08 5.584436817797448e-08 2.556231779042249e-24 -1.8490200188582156e-24 1.162494437753094e-24"/>
											<geom type="mesh" pos="0.06502872340548617 0.019881275921146812 0.291284182811854" euler="-1.5707963267948966 -7.546047120499112e-17 5.551115123125784e-17" mesh="hexapod_(stewart_platform)" material="soap"/>
										</body>
									</body>
								</body>
							</body>
							<body name="screw_rail_5" pos="0.0037816868458051267 0.008166936059518543 -0.13450000000000015" euler="-3.141592653589793 4.808436634973211e-16 8.326672684688673e-17">
								<inertial pos="6.785495153260879e-08 4.144883236981145e-09 -0.06995729955840327" mass="0.026593499421766056" fullinertia="4.153689516735653e-05 4.153679708207366e-05 1.0436631487447853e-07 -2.8481732232014794e-11 -2.5050200065244115e-12 2.8143002509461003e-12"/>
								<geom type="mesh" pos="0.12334623430328542 0.05347701781187486 -0.20410745429039476" euler="1.8258046081896517 -0.21209314925985848 -1.4195882980594374e-17" mesh="screw_rail" material="soap"/>
							</body>
						</body>
					</body>
				</body>
			</body>
			<body name="button_mount_6" pos="0.10949941936672206 0.03582814038716457 0.12639017447084194" euler="-3.141592653589793 1.6393136847980913e-16 -1.1102230246251617e-16">
				<inertial pos="1.0342509906835495e-07 2.790274292799322e-07 -0.003077680572704182" mass="0.004178185074547277" fullinertia="1.0610446632119487e-07 9.85540779840346e-08 4.16913240202048e-08 -3.6457066800702792e-09 3.0862070260273587e-14 1.3518352218491223e-12"/>
				<geom type="mesh" pos="0.12516982036650703 -0.05057189011115241 0.006000000000000033" euler="-1.5707963267948966 -1.0014835710813001e-32 1.232595164407831e-32" mesh="button_mount" material="soap"/>
				<body name="middle_connector_6" pos="0.0011238197811390127 0.002781551565908896 -0.012000000000000066" euler="-1.5707963267948963 0.47536848661658804 -0.3839724354388068">
					<joint class="joint_3" name="Revolute 16"/>
					<inertial pos="1.6653345369377348e-16 2.5157681053356297e-17 -0.0029999999999999814" mass="0.001730290612376196" fullinertia="1.0015092742718173e-08 1.0855626506660256e-08 9.929517797780883e-09 2.815167877202863e-10 -3.406309597255184e-23 4.347295869001985e-23"/>
					<geom type="mesh" pos="0.13499999999999307 -0.017999999999999974 -0.0029999999983105347" euler="2.9935352604471227e-17 -0.3839724354388087 1.0290277457786981e-17" mesh="middle_connector" material="soap"/>
					<body name="servo_6" pos="-0.0028703170603998074 0.000872513594608465 -0.0029999999999999055" euler="1.570796326794896 -1.0161211839251472 1.2756938852689232">
						<joint class="joint_3" name="Revolute 26"/>
						<inertial pos="0.025010960800872742 -0.04880528692318123 0.0028802998252503292" mass="0.42666054445271673" fullinertia="0.0002036110602117887 9.684476061580402e-05 0.0002397690426280824 7.419922435731003e-05 1.1445552576495995e-06 -1.7540567805251951e-06"/>
						<geom type="mesh" pos="0.012877003510459506 -0.017888479314477776 0.1373993492856463" euler="-2.459903094134618 -1.0910323282410475 -7.516624185445834e-17" mesh="servo" material="soap"/>
						<body name="box_arm_6" pos="0.03390301453257 -0.08589060254535602 0.0030000000023819584" euler="-1.5707963267948961 -1.1371444708654197 0.47357040291540264">
							<inertial pos="0.0037816915035426557 0.008166940396641334 -0.12258262431408148" mass="0.21032118837753752" fullinertia="0.0003632192697235533 0.00035960559317072487 2.575000070022534e-05 -2.1300013361813113e-06 4.6369633296342095e-12 1.8721776784007557e-11"/>
							<geom type="mesh" pos="0.12712792114909038 -0.045310081752356304 0.0701074542903947" euler="-1.3157880454001414 0.21209314925985803 0.0" mesh="box_arm" material="soap"/>
							<body name="box_6" pos="-1.3877787807814457e-16 -7.025630077706069e-17 -0.11912515675785373" euler="3.141592653589793 6.146558956254831e-15 6.730727086790022e-16">
								<joint class="joint_5" name="Slider 16"/>
								<inertial pos="0.003781686433903267 -0.008166935622419887 -0.014066006578610533" mass="0.1397363514714639" fullinertia="1.8745105677313276e-05 1.9393392171316494e-05 1.9816064282944407e-05 -3.821203064736334e-07 6.3447372937142454e-15 1.847551512005177e-13"/>
								<geom type="mesh" pos="0.12712792114909058 0.04531008175235634 -0.11372066320742896" euler="1.8258046081896517 -0.21209314925985798 -7.097941490297185e-18" mesh="box" material="soap"/>
								<body name="u_arm_6" pos="-0.004385249213713416 -0.011948622905323687 -0.0252" euler="8.673617379884042e-17 4.224051664003548e-16 3.816391647148996e-16">
									<inertial pos="0.008166936060305344 0.003781686845812259 0.09653292656690428" mass="0.07247635166987312" fullinertia="0.00015358024329046333 0.0001569298503914069 5.570917924441852e-06 -1.974360493859866e-06 -2.5471455119922777e-15 -1.5009975393643811e-16"/>
									<geom type="mesh" pos="0.13151317036280402 0.05725870465767999 -0.08852066320742888" euler="1.8258046081896517 -0.2120931492598584 -1.4195882980594374e-17" mesh="u_arm" material="soap"/>
									<body name="ball_6" pos="0.008166936059518681 0.0037816868458052 0.17520000000000024" euler="-1.22818422099158e-15 5.804818431487396e-16 -4.093947403305268e-16">
										<inertial pos="1.3877787807814457e-17 -1.1015433615375405e-16 3.469446951953614e-18" mass="0.0041102503884466466" fullinertia="4.110250388446647e-08 4.1102503884466455e-08 4.110250388446646e-08 -5.704118272784951e-25 5.124793760705234e-26 7.130147840981188e-26"/>
										<geom type="mesh" pos="0.06502872340548621 -0.2882631149999885 0.0198812759211468" euler="0.0 -2.233456475320139e-17 -1.3877787807814457e-17" mesh="ball" material="soap"/>
										<body name="hexapod_(stewart_platform)_6" pos="5.551115123125783e-17 -8.977193988179977e-17 -1.1102230246251565e-16" euler="2.9154407143239727 -0.0546742012535441 -1.6302393997628692">
											<joint class="joint_2" name="Ball 16"/>
											<inertial pos="-2.7755575615628914e-17 2.0816681711721685e-17 -0.0019720453168448103" mass="0.0026167634087740145" fullinertia="3.069931863351277e-08 3.069931863351278e-08 5.584436817797448e-08 8.520772596807497e-25 -2.1322864558928044e-24 6.492163924139637e-25"/>
											<geom type="mesh" pos="0.06502872340548617 0.01988127592114679 0.2912841828118539" euler="-1.5707963267948966 -6.93889390390723e-17 0.0" mesh="hexapod_(stewart_platform)" material="soap"/>
										</body>
									</body>
								</body>
							</body>
							<body name="screw_rail_6" pos="0.0037816868458051545 0.008166936059518543 -0.1345" euler="-3.141592653589793 1.4929463915125384e-16 -4.8572257327350556e-17">
								<inertial pos="6.785495147709764e-08 4.144883249124209e-09 -0.06995729955840319" mass="0.026593499421766056" fullinertia="4.153689516735653e-05 4.153679708207366e-05 1.0436631487447853e-07 -2.848173223116776e-11 -2.5050200088371915e-12 2.8143002487149103e-12"/>
								<geom type="mesh" pos="0.12334623430328537 0.053477017811874875 -0.20410745429039467" euler="1.8258046081896517 -0.21209314925985842 -7.097941490297187e-18" mesh="screw_rail" material="soap"/>
							</body>
						</body>
					</body>
				</body>
			</body>
		</body>
	</worldbody>
	<equality>
		<connect anchor="2.7755575615628914e-17 -1.214306433183765e-16 -0.000250000000000028" body1="hexapod_(stewart_platform)_2" body2="top"/>
		<connect anchor="1.3877787807814457e-17 -4.5102810375396984e-17 -0.00024999999999997247" body1="hexapod_(stewart_platform)_3" body2="top"/>
		<connect anchor="3.2959746043559335e-17 -8.673617379884035e-17 -0.000250000000000028" body1="hexapod_(stewart_platform)_4" body2="top"/>
		<connect anchor="-4.163336342344337e-17 -1.3183898417423734e-16 -0.00024999999999986144" body1="hexapod_(stewart_platform)_5" body2="top"/>
		<connect anchor="-7.632783294297951e-17 -3.122502256758253e-17 -0.00024999999999980593" body1="hexapod_(stewart_platform)_6" body2="top"/>
	</equality>
</mujoco>
